Workbook
Name CatReceita: OFFSET(Config!$B$6,0,0,MAX(1,SUMPRODUCT(--(LEN(Config!$B$6:$B$1000)>0))),1)
Name CatDespesa: OFFSET(Config!$D$6,0,0,MAX(1,SUMPRODUCT(--(LEN(Config!$D$6:$D$1000)>0))),1)
Name CatOutras: OFFSET(Config!$G$6,0,0,MAX(1,SUMPRODUCT(--(LEN(Config!$G$6:$G$1000)>0))),1)
Name Potes: OFFSET(Config!$I$6,0,0,MAX(1,SUMPRODUCT(--(LEN(Config!$I$6:$I$1000)>0))),1)
Name Pessoas: OFFSET(Config!$K$6,0,0,MAX(1,SUMPRODUCT(--(LEN(Config!$K$6:$K$1000)>0))),1)
Name ListaContas: OFFSET(Config!$M$6,0,0,MAX(1,SUMPRODUCT(--(LEN(Config!$M$6:$M$1000)>0))),1)
Name ListaCartoes: OFFSET(Config!$Q$6,0,0,MAX(1,SUMPRODUCT(--(LEN(Config!$Q$6:$Q$1000)>0))),1)
Name FormasPagamento: OFFSET(Config!$W$6,0,0,MAX(1,SUMPRODUCT(--(LEN(Config!$W$6:$W$1000)>0))),1)
Name Tipos: OFFSET(Config!$Y$6,0,0,MAX(1,SUMPRODUCT(--(LEN(Config!$Y$6:$Y$1000)>0))),1)
Name Situacoes: OFFSET(Config!$AA$6,0,0,MAX(1,SUMPRODUCT(--(LEN(Config!$AA$6:$AA$1000)>0))),1)
Name Anos: OFFSET(Config!$AG$6,0,0,MAX(1,SUMPRODUCT(--(LEN(Config!$AG$6:$AG$1000)>0))),1)
Name Meses: Config!$AD$6:$AD$17
Name MesesAbrev: Config!$AE$6:$AE$17
Name ListaFavoritos: OFFSET(Atalhos!$B$6,0,0,MAX(1,SUMPRODUCT(--(LEN(Atalhos!$B$6:$B$515)>0))),1)
Name MesNum: Calc!$B$2
Name Categorias: OFFSET(Calc!$AM$2,0,0,MAX(1,Calc!$B$20+Calc!$B$21+Calc!$B$27),1)
Name Contas: OFFSET(Calc!$AO$2,0,0,MAX(1,Calc!$B$22+Calc!$B$23),1)
Name MesSelecionado: Dashboard!$R$3
Name AnoSelecionado: Dashboard!$V$3

Sheet Inicio
B2: Central da Família | R2: MÊS DE REFERÊNCIA
B3: Tudo do dia a dia num lugar só: lance, confira as contas do mês e acompanhe o que vence. | R3: =MesSelecionado&" / "&AnoSelecionado | V3: =HYPERLINK("#Dashboard!A1","trocar no Dashboard ➜")
B5: =HYPERLINK("#Lancamentos!B"&(ROWS(tbLancamentos[Data])+5),"✚ Novo lançamento") | F5: =HYPERLINK("#ContasMes!A1","✔ Contas do mês") | J5: =HYPERLINK("#Parcelar!A1","⟳ Parcelar / repetir") | N5: =HYPERLINK("#Dashboard!A1","▦ Dashboard") | R5: =HYPERLINK("#Orcamento!A1","◎ Orçamento") | V5: =HYPERLINK("#Atalhos!A1","★ Favoritos")
B10: SALDO DO MÊS | F10: CONTAS FIXAS LANÇADAS | J10: A PAGAR NO MÊS | N10: ORÇAMENTO USADO | R10: A RECEBER (ACERTOS) | V10: INVESTIMENTOS (LÍQUIDO)
B11: =Calc!B13 | F11: =ContasMes!B6 | J11: =Calc!B28 | N11: =Calc!B18 | R11: =0 | V11: =0
B12: Poupança | C12: =Calc!B15 | F12: Falta lançar | G12: =ContasMes!G6 | J12: Atrasadas | K12: =Calc!B29 | N12: Meta total | O12: =Calc!B17 | R12: Parcelas | S12: =SUM(tbDividas[Saldo devedor]) | V12: Metas | W12: =SUM(tbMetas[Valor atual])
B15: Próximos vencimentos e atrasados | N15: Últimos lançamentos
B16: Vence | D16: Descrição | I16: Valor | K16: Status | N16: Data | P16: Descrição | U16: Categoria | W16: Valor
B17: =Calc!AW2 | D17: =Calc!AX2 | I17: =Calc!AY2 | K17: =Calc!AZ2 | N17: =Calc!BC2 | P17: =Calc!BD2 | U17: =Calc!BF2 | W17: =Calc!BE2
B18: =Calc!AW3 | D18: =Calc!AX3 | I18: =Calc!AY3 | K18: =Calc!AZ3 | N18: =Calc!BC3 | P18: =Calc!BD3 | U18: =Calc!BF3 | W18: =Calc!BE3
B19: =Calc!AW4 | D19: =Calc!AX4 | I19: =Calc!AY4 | K19: =Calc!AZ4 | N19: =Calc!BC4 | P19: =Calc!BD4 | U19: =Calc!BF4 | W19: =Calc!BE4
B20: =Calc!AW5 | D20: =Calc!AX5 | I20: =Calc!AY5 | K20: =Calc!AZ5 | N20: =Calc!BC5 | P20: =Calc!BD5 | U20: =Calc!BF5 | W20: =Calc!BE5
B21: =Calc!AW6 | D21: =Calc!AX6 | I21: =Calc!AY6 | K21: =Calc!AZ6 | N21: =Calc!BC6 | P21: =Calc!BD6 | U21: =Calc!BF6 | W21: =Calc!BE6
B22: =Calc!AW7 | D22: =Calc!AX7 | I22: =Calc!AY7 | K22: =Calc!AZ7 | N22: =Calc!BC7 | P22: =Calc!BD7 | U22: =Calc!BF7 | W22: =Calc!BE7
B23: =Calc!AW8 | D23: =Calc!AX8 | I23: =Calc!AY8 | K23: =Calc!AZ8 | N23: =Calc!BC8 | P23: =Calc!BD8 | U23: =Calc!BF8 | W23: =Calc!BE8
B24: =Calc!AW9 | D24: =Calc!AX9 | I24: =Calc!AY9 | K24: =Calc!AZ9 | N24: =Calc!BC9 | P24: =Calc!BD9 | U24: =Calc!BF9 | W24: =Calc!BE9
B26: Lançar em 10 segundos | N26: Rotina da família
B27: 1. ✚ Novo lançamento (botão acima) leva à primeira linha vazia. | N27: Toda semana: lançar os gastos (5 min) e conferir Próximos vencimentos.
B28: 2. Ctrl+; põe a data de hoje → Tab. | N28: Quando pagar uma conta: trocar Pendente ➜ Pago em Lançamentos.
B29: 3. Descrição: escolha um favorito (Alt+↓) ou digite → Tab. | N29: Início do mês: abrir ✔ Contas do mês e colar o bloco das contas que faltam.
B30: 4. Valor → Enter. Tipo, Categoria, Situação e Pote se preenchem sozinhos. | N30: Fim do mês: olhar o Dashboard e o Orçamento; ajustar metas se precisar.
B31: 5. Conta futura? Troque a Situação para Pendente; ela aparece em Próximos vencimentos. | N31: Sempre que mudar: novos favoritos em ★ Favoritos; listas na aba Config.
B32: Compra parcelada ou lançamento que se repete? Use ⟳ Parcelar / repetir. | N32: Atalhos úteis: Ctrl+D copia a célula de cima • Alt+↓ abre a lista • Ctrl+↓ vai ao fim.

Sheet Dashboard
B2: Finanças da Família | N2: =HYPERLINK("#Inicio!A1","⌂ Início") | R2: MÊS | V2: ANO
B3: Visão mensal — escolha o mês e o ano nos seletores à direita; tudo se atualiza sozinho. | N3: =HYPERLINK("#Lancamentos!B"&(ROWS(tbLancamentos[Data])+5),"✚ Novo lançamento") | R3: Setembro | V3: 2026
B6: RECEITAS DO MÊS | F6: GASTOS DO MÊS | J6: SALDO DO MÊS | N6: TAXA DE POUPANÇA | R6: GASTOS VS. MÊS ANTERIOR | V6: % DO ORÇAMENTO UTILIZADO
B7: =Calc!B9 | F7: =Calc!B10 | J7: =Calc!B13 | N7: =Calc!B15 | R7: =Calc!B16 | V7: =Calc!B18
B8: Mês anterior | C8: =Calc!B11 | F8: Mês anterior | G8: =Calc!B12 | J8: Mês anterior | K8: =Calc!B14 | N8: Mês anterior | O8: =Calc!B19 | R8: Diferença | S8: =Calc!B25 | V8: Meta total | W8: =Calc!B17
B51: Top 5 maiores gastos do mês | N51: Orçado × Realizado por categoria
B52: Data | D52: Descrição | I52: Categoria | K52: Valor | N52: Categoria | Q52: Meta | S52: Realizado | U52: Diferença | W52: % usado
B53: =Calc!AH2 | D53: =Calc!AI2 | I53: =Calc!AJ2 | K53: =Calc!AK2 | N53: =Calc!Z2 | Q53: =Calc!AA2 | S53: =Calc!AB2 | U53: =Q53-S53 | W53: =Calc!AC2
B54: =Calc!AH3 | D54: =Calc!AI3 | I54: =Calc!AJ3 | K54: =Calc!AK3 | N54: =Calc!Z3 | Q54: =Calc!AA3 | S54: =Calc!AB3 | U54: =Q54-S54 | W54: =Calc!AC3
B55: =Calc!AH4 | D55: =Calc!AI4 | I55: =Calc!AJ4 | K55: =Calc!AK4 | N55: =Calc!Z4 | Q55: =Calc!AA4 | S55: =Calc!AB4 | U55: =Q55-S55 | W55: =Calc!AC4
B56: =Calc!AH5 | D56: =Calc!AI5 | I56: =Calc!AJ5 | K56: =Calc!AK5 | N56: =Calc!Z5 | Q56: =Calc!AA5 | S56: =Calc!AB5 | U56: =Q56-S56 | W56: =Calc!AC5
B57: =Calc!AH6 | D57: =Calc!AI6 | I57: =Calc!AJ6 | K57: =Calc!AK6 | N57: =Calc!Z6 | Q57: =Calc!AA6 | S57: =Calc!AB6 | U57: =Q57-S57 | W57: =Calc!AC6
N58: =Calc!Z7 | Q58: =Calc!AA7 | S58: =Calc!AB7 | U58: =Q58-S58 | W58: =Calc!AC7
B59: Como usar | N59: =Calc!Z8 | Q59: =Calc!AA8 | S59: =Calc!AB8 | U59: =Q59-S59 | W59: =Calc!AC8
B60: 1. Lance receitas e gastos na aba Lançamentos (valor sempre positivo). | N60: =Calc!Z9 | Q60: =Calc!AA9 | S60: =Calc!AB9 | U60: =Q60-S60 | W60: =Calc!AC9
B61: 2. Troque o mês/ano no topo: tudo se atualiza sozinho. | N61: =Calc!Z10 | Q61: =Calc!AA10 | S61: =Calc!AB10 | U61: =Q61-S61 | W61: =Calc!AC10
B62: 3. Ajuste metas na aba Orçamento e listas na aba Config. | N62: =Calc!Z11 | Q62: =Calc!AA11 | S62: =Calc!AB11 | U62: =Q62-S62 | W62: =Calc!AC11
B63: 4. Só entra nos totais o que tem 'Conta no mês?' = sim. | N63: =Calc!Z12 | Q63: =Calc!AA12 | S63: =Calc!AB12 | U63: =Q63-S63 | W63: =Calc!AC12
B64: % usado: verde até 80% • amarelo 80–100% • vermelho acima de 100%. | N64: =Calc!Z13 | Q64: =Calc!AA13 | S64: =Calc!AB13 | U64: =Q64-S64 | W64: =Calc!AC13

Sheet Lancamentos
B2: Lançamentos | E2: =HYPERLINK("#Lancamentos!B"&(ROWS(tbLancamentos[Data])+5),"✚ Ir para a próxima linha vazia") | G2: =HYPERLINK("#Inicio!A1","⌂ Início")
B3: Digite Data, Descrição e Valor: com um favorito, Tipo, Categoria, Situação e Pote se preenchem sozinhos. Clique no [+] acima das colunas para ver os detalhes (conta, parcela, vencimento...). Linhas com "EXEMPLO" na Observação são dados fictícios: filtre e apague quando quiser.
B4: Data | C4: Descrição | D4: Valor | E4: Tipo | F4: Categoria | G4: Situação | H4: Pote | I4: Quem | J4: Conta | K4: Forma de pagamento | L4: Parcela | M4: Vencimento | N4: Competência | O4: Subcategoria | P4: Descontar de | Q4: Observação | R4: Mês | S4: Ano | T4: Conta no mês?
B5: 46115 | C5: Plano de saúde familiar | D5: 890 | E5: Despesa | F5: Saúde | G5: Pago | H5: Essenciais | J5: Conta corrente Itaú | K5: Débito automático | O5: Plano de saúde | Q5: EXEMPLO | R5: =IF(AND(tbLancamentos[[#This Row],[Data]]="",tbLancamentos[[#This Row],[Competência]]=""),"",MONTH(IF(tbLancamentos[[#This Row],[Competência]]<>"",tbLancamentos[[#This Row],[Competência]],tbLancamentos[[#This Row],[Data]]))) | S5: =IF(AND(tbLancamentos[[#This Row],[Data]]="",tbLancamentos[[#This Row],[Competência]]=""),"",YEAR(IF(tbLancamentos[[#This Row],[Competência]]<>"",tbLancamentos[[#This Row],[Competência]],tbLancamentos[[#This Row],[Data]]))) | T5: =IF(tbLancamentos[[#This Row],[Valor]]="","",IF(AND(tbLancamentos[[#This Row],[Tipo]]<>"Investimento",OR(tbLancamentos[[#This Row],[Situação]]="",tbLancamentos[[#This Row],[Situação]]="Pago",tbLancamentos[[#This Row],[Situação]]="Recebido",tbLancamentos[[#This Row],[Situação]]="Descontar Depois")),"sim","não"))
B6: 46117 | C6: Salário — titular | D6: 7800 | E6: Receita | F6: Salário | G6: Recebido | J6: Conta corrente Itaú | K6: Transferência | O6: Mensal | Q6: EXEMPLO | R6: =IF(AND(tbLancamentos[[#This Row],[Data]]="",tbLancamentos[[#This Row],[Competência]]=""),"",MONTH(IF(tbLancamentos[[#This Row],[Competência]]<>"",tbLancamentos[[#This Row],[Competência]],tbLancamentos[[#This Row],[Data]]))) | S6: =IF(AND(tbLancamentos[[#This Row],[Data]]="",tbLancamentos[[#This Row],[Competência]]=""),"",YEAR(IF(tbLancamentos[[#This Row],[Competência]]<>"",tbLancamentos[[#This Row],[Competência]],tbLancamentos[[#This Row],[Data]]))) | T6: =IF(tbLancamentos[[#This Row],[Valor]]="","",IF(AND(tbLancamentos[[#This Row],[Tipo]]<>"Investimento",OR(tbLancamentos[[#This Row],[Situação]]="",tbLancamentos[[#This Row],[Situação]]="Pago",tbLancamentos[[#This Row],[Situação]]="Recebido",tbLancamentos[[#This Row],[Situação]]="Descontar Depois")),"sim","não"))
B7: 46117 | C7: Salário — cônjuge | D7: 5200 | E7: Receita | F7: Salário | G7: Recebido | J7: Conta Nubank | K7: Transferência | O7: Mensal | Q7: EXEMPLO | R7: =IF(AND(tbLancamentos[[#This Row],[Data]]="",tbLancamentos[[#This Row],[Competência]]=""),"",MONTH(IF(tbLancamentos[[#This Row],[Competência]]<>"",tbLancamentos[[#This Row],[Competência]],tbLancamentos[[#This Row],[Data]]))) | S7: =IF(AND(tbLancamentos[[#This Row],[Data]]="",tbLancamentos[[#This Row],[Competência]]=""),"",YEAR(IF(tbLancamentos[[#This Row],[Competência]]<>"",tbLancamentos[[#This Row],[Competência]],tbLancamentos[[#This Row],[Data]]))) | T7: =IF(tbLancamentos[[#This Row],[Valor]]="","",IF(AND(tbLancamentos[[#This Row],[Tipo]]<>"Investimento",OR(tbLancamentos[[#This Row],[Situação]]="",tbLancamentos[[#This Row],[Situação]]="Pago",tbLancamentos[[#This Row],[Situação]]="Recebido",tbLancamentos[[#This Row],[Situação]]="Descontar Depois")),"sim","não"))
B8: 46119 | C8: Mercado do mês | D8: 842.37 | E8: Despesa | F8: Alimentação | G8: Pago | H8: Essenciais | J8: Cartão Nubank | K8: Cartão de crédito | O8: Mercado | Q8: EXEMPLO | R8: =IF(AND(tbLancamentos[[#This Row],[Data]]="",tbLancamentos[[#This Row],[Competência]]=""),"",MONTH(IF(tbLancamentos[[#This Row],[Competência]]<>"",tbLancamentos[[#This Row],[Competência]],tbLancamentos[[#This Row],[Data]]))) | S8: =IF(AND(tbLancamentos[[#This Row],[Data]]="",tbLancamentos[[#This Row],[Competência]]=""),"",YEAR(IF(tbLancamentos[[#This Row],[Competência]]<>"",tbLancamentos[[#This Row],[Competência]],tbLancamentos[[#This Row],[Data]]))) | T8: =IF(tbLancamentos[[#This Row],[Valor]]="","",IF(AND(tbLancamentos[[#This Row],[Tipo]]<>"Investimento",OR(tbLancamentos[[#This Row],[Situação]]="",tbLancamentos[[#This Row],[Situação]]="Pago",tbLancamentos[[#This Row],[Situação]]="Recebido",tbLancamentos[[#This Row],[Situação]]="Descontar Depois")),"sim","não"))
B9: 46120 | C9: Mensalidade escolar | D9: 1450 | E9: Despesa | F9: Educação | G9: Pago | H9: Essenciais | J9: Conta corrente Itaú | K9: Boleto | O9: Escola | Q9: EXEMPLO | R9: =IF(AND(tbLancamentos[[#This Row],[Data]]="",tbLancamentos[[#This Row],[Competência]]=""),"",MONTH(IF(tbLancamentos[[#This Row],[Competência]]<>"",tbLancamentos[[#This Row],[Competência]],tbLancamentos[[#This Row],[Data]]))) | S9: =IF(AND(tbLancamentos[[#This Row],[Data]]="",tbLancamentos[[#This Row],[Competência]]=""),"",YEAR(IF(tbLancamentos[[#This Row],[Competência]]<>"",tbLancamentos[[#This Row],[Competência]],tbLancamentos[[#This Row],[Data]]))) | T9: =IF(tbLancamentos[[#This Row],[Valor]]="","",IF(AND(tbLancamentos[[#This Row],[Tipo]]<>"Investimento",OR(tbLancamentos[[#This Row],[Situação]]="",tbLancamentos[[#This Row],[Situação]]="Pago",tbLancamentos[[#This Row],[Situação]]="Recebido",tbLancamentos[[#This Row],[Situação]]="Descontar Depois")),"sim","não"))
B10: 46122 | C10: Aluguel do apartamento | D10: 2350 | E10: Despesa | F10: Moradia | G10: Pago | H10: Essenciais | J10: Conta corrente Itaú | K10: Boleto | O10: Aluguel/Financiamento | Q10: EXEMPLO | R10: =IF(AND(tbLancamentos[[#This Row],[Data]]="",tbLancamentos[[#This Row],[Competência]]=""),"",MONTH(IF(tbLancamentos[[#This Row],[Competência]]<>"",tbLancamentos[[#This Row],[Competência]],tbLancamentos[[#This Row],[Data]]))) | S10: =IF(AND(tbLancamentos[[#This Row],[Data]]="",tbLancamentos[[#This Row],[Competência]]=""),"",YEAR(IF(tbLancamentos[[#This Row],[Competência]]<>"",tbLancamentos[[#This Row],[Competência]],tbLancamentos[[#This Row],[Data]]))) | T10: =IF(tbLancamentos[[#This Row],[Valor]]="","",IF(AND(tbLancamentos[[#This Row],[Tipo]]<>"Investimento",OR(tbLancamentos[[#This Row],[Situação]]="",tbLancamentos[[#This Row],[Situação]]="Pago",tbLancamentos[[#This Row],[Situação]]="Recebido",tbLancamentos[[#This Row],[Situação]]="Descontar Depois")),"sim","não"))
B11: 46122 | C11: Conta de energia | D11: 312.4 | E11: Despesa | F11: Contas da casa | G11: Pago | H11: Essenciais | J11: Conta corrente Itaú | K11: Débito automático | O11: Energia | Q11: EXEMPLO | R11: =IF(AND(tbLancamentos[[#This Row],[Data]]="",tbLancamentos[[#This Row],[Competência]]=""),"",MONTH(IF(tbLancamentos[[#This Row],[Competência]]<>"",tbLancamentos[[#This Row],[Competência]],tbLancamentos[[#This Row],[Data]]))) | S11: =IF(AND(tbLancamentos[[#This Row],[Data]]="",tbLancamentos[[#This Row],[Competência]]=""),"",YEAR(IF(tbLancamentos[[#This Row],[Competência]]<>"",tbLancamentos[[#This Row],[Competência]],tbLancamentos[[#This Row],[Data]]))) | T11: =IF(tbLancamentos[[#This Row],[Valor]]="","",IF(AND(tbLancamentos[[#This Row],[Tipo]]<>"Investimento",OR(tbLancamentos[[#This Row],[Situação]]="",tbLancamentos[[#This Row],[Situação]]="Pago",tbLancamentos[[#This Row],[Situação]]="Recebido",tbLancamentos[[#This Row],[Situação]]="Descontar Depois")),"sim","não"))
B12: 46124 | C12: Streaming + academia | D12: 174.8 | E12: Despesa | F12: Assinaturas | G12: Pago | H12: Essenciais | J12: Cartão Nubank | K12: Cartão de crédito | O12: Streaming | Q12: EXEMPLO | R12: =IF(AND(tbLancamentos[[#This Row],[Data]]="",tbLancamentos[[#This Row],[Competência]]=""),"",MONTH(IF(tbLancamentos[[#This Row],[Competência]]<>"",tbLancamentos[[#This Row],[Competência]],tbLancamentos[[#This Row],[Data]]))) | S12: =IF(AND(tbLancamentos[[#This Row],[Data]]="",tbLancamentos[[#This Row],[Competência]]=""),"",YEAR(IF(tbLancamentos[[#This Row],[Competência]]<>"",tbLancamentos[[#This Row],[Competência]],tbLancamentos[[#This Row],[Data]]))) | T12: =IF(tbLancamentos[[#This Row],[Valor]]="","",IF(AND(tbLancamentos[[#This Row],[Tipo]]<>"Investimento",OR(tbLancamentos[[#This Row],[Situação]]="",tbLancamentos[[#This Row],[Situação]]="Pago",tbLancamentos[[#This Row],[Situação]]="Recebido",tbLancamentos[[#This Row],[Situação]]="Descontar Depois")),"sim","não"))
B13: 46127 | C13: Combustível | D13: 310 | E13: Despesa | F13: Transporte | G13: Pago | H13: Essenciais | J13: Cartão Itaú | K13: Cartão de crédito | O13: Combustível | Q13: EXEMPLO | R13: =IF(AND(tbLancamentos[[#This Row],[Data]]="",tbLancamentos[[#This Row],[Competência]]=""),"",MONTH(IF(tbLancamentos[[#This Row],[Competência]]<>"",tbLancamentos[[#This Row],[Competência]],tbLancamentos[[#This Row],[Data]]))) | S13: =IF(AND(tbLancamentos[[#This Row],[Data]]="",tbLancamentos[[#This Row],[Competência]]=""),"",YEAR(IF(tbLancamentos[[#This Row],[Competência]]<>"",tbLancamentos[[#This Row],[Competência]],tbLancamentos[[#This Row],[Data]]))) | T13: =IF(tbLancamentos[[#This Row],[Valor]]="","",IF(AND(tbLancamentos[[#This Row],[Tipo]]<>"Investimento",OR(tbLancamentos[[#This Row],[Situação]]="",tbLancamentos[[#This Row],[Situação]]="Pago",tbLancamentos[[#This Row],[Situação]]="Recebido",tbLancamentos[[#This Row],[Situação]]="Descontar Depois")),"sim","não"))
B14: 46130 | C14: Farmácia | D14: 142.35 | E14: Despesa | F14: Saúde | G14: Pago | H14: Essenciais | J14: Cartão Nubank | K14: Cartão de crédito | O14: Farmácia | Q14: EXEMPLO | R14: =IF(AND(tbLancamentos[[#This Row],[Data]]="",tbLancamentos[[#This Row],[Competência]]=""),"",MONTH(IF(tbLancamentos[[#This Row],[Competência]]<>"",tbLancamentos[[#This Row],[Competência]],tbLancamentos[[#This Row],[Data]]))) | S14: =IF(AND(tbLancamentos[[#This Row],[Data]]="",tbLancamentos[[#This Row],[Competência]]=""),"",YEAR(IF(tbLancamentos[[#This Row],[Competência]]<>"",tbLancamentos[[#This Row],[Competência]],tbLancamentos[[#This Row],[Data]]))) | T14: =IF(tbLancamentos[[#This Row],[Valor]]="","",IF(AND(tbLancamentos[[#This Row],[Tipo]]<>"Investimento",OR(tbLancamentos[[#This Row],[Situação]]="",tbLancamentos[[#This Row],[Situação]]="Pago",tbLancamentos[[#This Row],[Situação]]="Recebido",tbLancamentos[[#This Row],[Situação]]="Descontar Depois")),"sim","não"))
B15: 46138 | C15: Pizza de sábado | D15: 118 | E15: Despesa | F15: Restaurantes e delivery | G15: Pago | H15: Lazer | J15: Cartão Nubank | K15: Cartão de crédito | O15: Delivery | Q15: EXEMPLO | R15: =IF(AND(tbLancamentos[[#This Row],[Data]]="",tbLancamentos[[#This Row],[Competência]]=""),"",MONTH(IF(tbLancamentos[[#This Row],[Competência]]<>"",tbLancamentos[[#This Row],[Competência]],tbLancamentos[[#This Row],[Data]]))) | S15: =IF(AND(tbLancamentos[[#This Row],[Data]]="",tbLancamentos[[#This Row],[Competência]]=""),"",YEAR(IF(tbLancamentos[[#This Row],[Competência]]<>"",tbLancamentos[[#This Row],[Competência]],tbLancamentos[[#This Row],[Data]]))) | T15: =IF(tbLancamentos[[#This Row],[Valor]]="","",IF(AND(tbLancamentos[[#This Row],[Tipo]]<>"Investimento",OR(tbLancamentos[[#This Row],[Situação]]="",tbLancamentos[[#This Row],[Situação]]="Pago",tbLancamentos[[#This Row],[Situação]]="Recebido",tbLancamentos[[#This Row],[Situação]]="Descontar Depois")),"sim","não"))
B16: 46139 | C16: Cinema / passeio | D16: 64 | E16: Despesa | F16: Lazer | G16: Pago | H16: Lazer | J16: Conta Nubank | K16: PIX | O16: Cinema | Q16: EXEMPLO | R16: =IF(AND(tbLancamentos[[#This Row],[Data]]="",tbLancamentos[[#This Row],[Competência]]=""),"",MONTH(IF(tbLancamentos[[#This Row],[Competência]]<>"",tbLancamentos[[#This Row],[Competência]],tbLancamentos[[#This Row],[Data]]))) | S16: =IF(AND(tbLancamentos[[#This Row],[Data]]="",tbLancamentos[[#This Row],[Competência]]=""),"",YEAR(IF(tbLancamentos[[#This Row],[Competência]]<>"",tbLancamentos[[#This Row],[Competência]],tbLancamentos[[#This Row],[Data]]))) | T16: =IF(tbLancamentos[[#This Row],[Valor]]="","",IF(AND(tbLancamentos[[#This Row],[Tipo]]<>"Investimento",OR(tbLancamentos[[#This Row],[Situação]]="",tbLancamentos[[#This Row],[Situação]]="Pago",tbLancamentos[[#This Row],[Situação]]="Recebido",tbLancamentos[[#This Row],[Situação]]="Descontar Depois")),"sim","não"))
B17: 46145 | C17: Plano de saúde familiar | D17: 890 | E17: Despesa | F17: Saúde | G17: Pago | H17: Essenciais | J17: Conta corrente Itaú | K17: Débito automático | O17: Plano de saúde | Q17: EXEMPLO | R17: =IF(AND(tbLancamentos[[#This Row],[Data]]="",tbLancamentos[[#This Row],[Competência]]=""),"",MONTH(IF(tbLancamentos[[#This Row],[Competência]]<>"",tbLancamentos[[#This Row],[Competência]],tbLancamentos[[#This Row],[Data]]))) | S17: =IF(AND(tbLancamentos[[#This Row],[Data]]="",tbLancamentos[[#This Row],[Competência]]=""),"",YEAR(IF(tbLancamentos[[#This Row],[Competência]]<>"",tbLancamentos[[#This Row],[Competência]],tbLancamentos[[#This Row],[Data]]))) | T17: =IF(tbLancamentos[[#This Row],[Valor]]="","",IF(AND(tbLancamentos[[#This Row],[Tipo]]<>"Investimento",OR(tbLancamentos[[#This Row],[Situação]]="",tbLancamentos[[#This Row],[Situação]]="Pago",tbLancamentos[[#This Row],[Situação]]="Recebido",tbLancamentos[[#This Row],[Situação]]="Descontar Depois")),"sim","não"))
B18: 46147 | C18: Salário — titular | D18: 7800 | E18: Receita | F18: Salário | G18: Recebido | J18: Conta corrente Itaú | K18: Transferência | O18: Mensal | Q18: EXEMPLO | R18: =IF(AND(tbLancamentos[[#This Row],[Data]]="",tbLancamentos[[#This Row],[Competência]]=""),"",MONTH(IF(tbLancamentos[[#This Row],[Competência]]<>"",tbLancamentos[[#This Row],[Competência]],tbLancamentos[[#This Row],[Data]]))) | S18: =IF(AND(tbLancamentos[[#This Row],[Data]]="",tbLancamentos[[#This Row],[Competência]]=""),"",YEAR(IF(tbLancamentos[[#This Row],[Competência]]<>"",tbLancamentos[[#This Row],[Competência]],tbLancamentos[[#This Row],[Data]]))) | T18: =IF(tbLancamentos[[#This Row],[Valor]]="","",IF(AND(tbLancamentos[[#This Row],[Tipo]]<>"Investimento",OR(tbLancamentos[[#This Row],[Situação]]="",tbLancamentos[[#This Row],[Situação]]="Pago",tbLancamentos[[#This Row],[Situação]]="Recebido",tbLancamentos[[#This Row],[Situação]]="Descontar Depois")),"sim","não"))
B19: 46147 | C19: Salário — cônjuge | D19: 5200 | E19: Receita | F19: Salário | G19: Recebido | J19: Conta Nubank | K19: Transferência | O19: Mensal | Q19: EXEMPLO | R19: =IF(AND(tbLancamentos[[#This Row],[Data]]="",tbLancamentos[[#This Row],[Competência]]=""),"",MONTH(IF(tbLancamentos[[#This Row],[Competência]]<>"",tbLancamentos[[#This Row],[Competência]],tbLancamentos[[#This Row],[Data]]))) | S19: =IF(AND(tbLancamentos[[#This Row],[Data]]="",tbLancamentos[[#This Row],[Competência]]=""),"",YEAR(IF(tbLancamentos[[#This Row],[Competência]]<>"",tbLancamentos[[#This Row],[Competência]],tbLancamentos[[#This Row],[Data]]))) | T19: =IF(tbLancamentos[[#This Row],[Valor]]="","",IF(AND(tbLancamentos[[#This Row],[Tipo]]<>"Investimento",OR(tbLancamentos[[#This Row],[Situação]]="",tbLancamentos[[#This Row],[Situação]]="Pago",tbLancamentos[[#This Row],[Situação]]="Recebido",tbLancamentos[[#This Row],[Situação]]="Descontar Depois")),"sim","não"))
B20: 46149 | C20: Mercado do mês | D20: 915.6 | E20: Despesa | F20: Alimentação | G20: Pago | H20: Essenciais | J20: Cartão Nubank | K20: Cartão de crédito | O20: Mercado | Q20: EXEMPLO | R20: =IF(AND(tbLancamentos[[#This Row],[Data]]="",tbLancamentos[[#This Row],[Competência]]=""),"",MONTH(IF(tbLancamentos[[#This Row],[Competência]]<>"",tbLancamentos[[#This Row],[Competência]],tbLancamentos[[#This Row],[Data]]))) | S20: =IF(AND(tbLancamentos[[#This Row],[Data]]="",tbLancamentos[[#This Row],[Competência]]=""),"",YEAR(IF(tbLancamentos[[#This Row],[Competência]]<>"",tbLancamentos[[#This Row],[Competência]],tbLancamentos[[#This Row],[Data]]))) | T20: =IF(tbLancamentos[[#This Row],[Valor]]="","",IF(AND(tbLancamentos[[#This Row],[Tipo]]<>"Investimento",OR(tbLancamentos[[#This Row],[Situação]]="",tbLancamentos[[#This Row],[Situação]]="Pago",tbLancamentos[[#This Row],[Situação]]="Recebido",tbLancamentos[[#This Row],[Situação]]="Descontar Depois")),"sim","não"))
B21: 46150 | C21: Mensalidade escolar | D21: 1450 | E21: Despesa | F21: Educação | G21: Pago | H21: Essenciais | J21: Conta corrente Itaú | K21: Boleto | O21: Escola | Q21: EXEMPLO | R21: =IF(AND(tbLancamentos[[#This Row],[Data]]="",tbLancamentos[[#This Row],[Competência]]=""),"",MONTH(IF(tbLancamentos[[#This Row],[Competência]]<>"",tbLancamentos[[#This Row],[Competência]],tbLancamentos[[#This Row],[Data]]))) | S21: =IF(AND(tbLancamentos[[#This Row],[Data]]="",tbLancamentos[[#This Row],[Competência]]=""),"",YEAR(IF(tbLancamentos[[#This Row],[Competência]]<>"",tbLancamentos[[#This Row],[Competência]],tbLancamentos[[#This Row],[Data]]))) | T21: =IF(tbLancamentos[[#This Row],[Valor]]="","",IF(AND(tbLancamentos[[#This Row],[Tipo]]<>"Investimento",OR(tbLancamentos[[#This Row],[Situação]]="",tbLancamentos[[#This Row],[Situação]]="Pago",tbLancamentos[[#This Row],[Situação]]="Recebido",tbLancamentos[[#This Row],[Situação]]="Descontar Depois")),"sim","não"))
B22: 46152 | C22: Aluguel do apartamento | D22: 2350 | E22: Despesa | F22: Moradia | G22: Pago | H22: Essenciais | J22: Conta corrente Itaú | K22: Boleto | O22: Aluguel/Financiamento | Q22: EXEMPLO | R22: =IF(AND(tbLancamentos[[#This Row],[Data]]="",tbLancamentos[[#This Row],[Competência]]=""),"",MONTH(IF(tbLancamentos[[#This Row],[Competência]]<>"",tbLancamentos[[#This Row],[Competência]],tbLancamentos[[#This Row],[Data]]))) | S22: =IF(AND(tbLancamentos[[#This Row],[Data]]="",tbLancamentos[[#This Row],[Competência]]=""),"",YEAR(IF(tbLancamentos[[#This Row],[Competência]]<>"",tbLancamentos[[#This Row],[Competência]],tbLancamentos[[#This Row],[Data]]))) | T22: =IF(tbLancamentos[[#This Row],[Valor]]="","",IF(AND(tbLancamentos[[#This Row],[Tipo]]<>"Investimento",OR(tbLancamentos[[#This Row],[Situação]]="",tbLancamentos[[#This Row],[Situação]]="Pago",tbLancamentos[[#This Row],[Situação]]="Recebido",tbLancamentos[[#This Row],[Situação]]="Descontar Depois")),"sim","não"))
B23: 46152 | C23: Conta de energia | D23: 286.15 | E23: Despesa | F23: Contas da casa | G23: Pago | H23: Essenciais | J23: Conta corrente Itaú | K23: Débito automático | O23: Energia | Q23: EXEMPLO | R23: =IF(AND(tbLancamentos[[#This Row],[Data]]="",tbLancamentos[[#This Row],[Competência]]=""),"",MONTH(IF(tbLancamentos[[#This Row],[Competência]]<>"",tbLancamentos[[#This Row],[Competência]],tbLancamentos[[#This Row],[Data]]))) | S23: =IF(AND(tbLancamentos[[#This Row],[Data]]="",tbLancamentos[[#This Row],[Competência]]=""),"",YEAR(IF(tbLancamentos[[#This Row],[Competência]]<>"",tbLancamentos[[#This Row],[Competência]],tbLancamentos[[#This Row],[Data]]))) | T23: =IF(tbLancamentos[[#This Row],[Valor]]="","",IF(AND(tbLancamentos[[#This Row],[Tipo]]<>"Investimento",OR(tbLancamentos[[#This Row],[Situação]]="",tbLancamentos[[#This Row],[Situação]]="Pago",tbLancamentos[[#This Row],[Situação]]="Recebido",tbLancamentos[[#This Row],[Situação]]="Descontar Depois")),"sim","não"))
B24: 46154 | C24: Streaming + academia | D24: 174.8 | E24: Despesa | F24: Assinaturas | G24: Pago | H24: Essenciais | J24: Cartão Nubank | K24: Cartão de crédito | O24: Streaming | Q24: EXEMPLO | R24: =IF(AND(tbLancamentos[[#This Row],[Data]]="",tbLancamentos[[#This Row],[Competência]]=""),"",MONTH(IF(tbLancamentos[[#This Row],[Competência]]<>"",tbLancamentos[[#This Row],[Competência]],tbLancamentos[[#This Row],[Data]]))) | S24: =IF(AND(tbLancamentos[[#This Row],[Data]]="",tbLancamentos[[#This Row],[Competência]]=""),"",YEAR(IF(tbLancamentos[[#This Row],[Competência]]<>"",tbLancamentos[[#This Row],[Competência]],tbLancamentos[[#This Row],[Data]]))) | T24: =IF(tbLancamentos[[#This Row],[Valor]]="","",IF(AND(tbLancamentos[[#This Row],[Tipo]]<>"Investimento",OR(tbLancamentos[[#This Row],[Situação]]="",tbLancamentos[[#This Row],[Situação]]="Pago",tbLancamentos[[#This Row],[Situação]]="Recebido",tbLancamentos[[#This Row],[Situação]]="Descontar Depois")),"sim","não"))
B25: 46154 | C25: Projeto freelance — site | D25: 1800 | E25: Receita | F25: Freelance / Extras | G25: Recebido | J25: Conta Nubank | K25: PIX | O25: Projeto | Q25: EXEMPLO | R25: =IF(AND(tbLancamentos[[#This Row],[Data]]="",tbLancamentos[[#This Row],[Competência]]=""),"",MONTH(IF(tbLancamentos[[#This Row],[Competência]]<>"",tbLancamentos[[#This Row],[Competência]],tbLancamentos[[#This Row],[Data]]))) | S25: =IF(AND(tbLancamentos[[#This Row],[Data]]="",tbLancamentos[[#This Row],[Competência]]=""),"",YEAR(IF(tbLancamentos[[#This Row],[Competência]]<>"",tbLancamentos[[#This Row],[Competência]],tbLancamentos[[#This Row],[Data]]))) | T25: =IF(tbLancamentos[[#This Row],[Valor]]="","",IF(AND(tbLancamentos[[#This Row],[Tipo]]<>"Investimento",OR(tbLancamentos[[#This Row],[Situação]]="",tbLancamentos[[#This Row],[Situação]]="Pago",tbLancamentos[[#This Row],[Situação]]="Recebido",tbLancamentos[[#This Row],[Situação]]="Descontar Depois")),"sim","não"))
B26: 46157 | C26: Combustível | D26: 285.5 | E26: Despesa | F26: Transporte | G26: Pago | H26: Essenciais | J26: Cartão Itaú | K26: Cartão de crédito | O26: Combustível | Q26: EXEMPLO | R26: =IF(AND(tbLancamentos[[#This Row],[Data]]="",tbLancamentos[[#This Row],[Competência]]=""),"",MONTH(IF(tbLancamentos[[#This Row],[Competência]]<>"",tbLancamentos[[#This Row],[Competência]],tbLancamentos[[#This Row],[Data]]))) | S26: =IF(AND(tbLancamentos[[#This Row],[Data]]="",tbLancamentos[[#This Row],[Competência]]=""),"",YEAR(IF(tbLancamentos[[#This Row],[Competência]]<>"",tbLancamentos[[#This Row],[Competência]],tbLancamentos[[#This Row],[Data]]))) | T26: =IF(tbLancamentos[[#This Row],[Valor]]="","",IF(AND(tbLancamentos[[#This Row],[Tipo]]<>"Investimento",OR(tbLancamentos[[#This Row],[Situação]]="",tbLancamentos[[#This Row],[Situação]]="Pago",tbLancamentos[[#This Row],[Situação]]="Recebido",tbLancamentos[[#This Row],[Situação]]="Descontar Depois")),"sim","não"))
B27: 46166 | C27: Presente dia das mães | D27: 289.9 | E27: Despesa | F27: Compras | G27: Pago | H27: Essenciais | J27: Cartão Itaú | K27: Cartão de crédito | O27: Presentes | Q27: EXEMPLO | R27: =IF(AND(tbLancamentos[[#This Row],[Data]]="",tbLancamentos[[#This Row],[Competência]]=""),"",MONTH(IF(tbLancamentos[[#This Row],[Competência]]<>"",tbLancamentos[[#This Row],[Competência]],tbLancamentos[[#This Row],[Data]]))) | S27: =IF(AND(tbLancamentos[[#This Row],[Data]]="",tbLancamentos[[#This Row],[Competência]]=""),"",YEAR(IF(tbLancamentos[[#This Row],[Competência]]<>"",tbLancamentos[[#This Row],[Competência]],tbLancamentos[[#This Row],[Data]]))) | T27: =IF(tbLancamentos[[#This Row],[Valor]]="","",IF(AND(tbLancamentos[[#This Row],[Tipo]]<>"Investimento",OR(tbLancamentos[[#This Row],[Situação]]="",tbLancamentos[[#This Row],[Situação]]="Pago",tbLancamentos[[#This Row],[Situação]]="Recebido",tbLancamentos[[#This Row],[Situação]]="Descontar Depois")),"sim","não"))
B28: 46169 | C28: Cinema / passeio | D28: 180 | E28: Despesa | F28: Lazer | G28: Pago | H28: Lazer | J28: Conta Nubank | K28: PIX | O28: Cinema | Q28: EXEMPLO | R28: =IF(AND(tbLancamentos[[#This Row],[Data]]="",tbLancamentos[[#This Row],[Competência]]=""),"",MONTH(IF(tbLancamentos[[#This Row],[Competência]]<>"",tbLancamentos[[#This Row],[Competência]],tbLancamentos[[#This Row],[Data]]))) | S28: =IF(AND(tbLancamentos[[#This Row],[Data]]="",tbLancamentos[[#This Row],[Competência]]=""),"",YEAR(IF(tbLancamentos[[#This Row],[Competência]]<>"",tbLancamentos[[#This Row],[Competência]],tbLancamentos[[#This Row],[Data]]))) | T28: =IF(tbLancamentos[[#This Row],[Valor]]="","",IF(AND(tbLancamentos[[#This Row],[Tipo]]<>"Investimento",OR(tbLancamentos[[#This Row],[Situação]]="",tbLancamentos[[#This Row],[Situação]]="Pago",tbLancamentos[[#This Row],[Situação]]="Recebido",tbLancamentos[[#This Row],[Situação]]="Descontar Depois")),"sim","não"))
B29: 46176 | C29: Plano de saúde familiar | D29: 890 | E29: Despesa | F29: Saúde | G29: Pago | H29: Essenciais | J29: Conta corrente Itaú | K29: Débito automático | O29: Plano de saúde | Q29: EXEMPLO | R29: =IF(AND(tbLancamentos[[#This Row],[Data]]="",tbLancamentos[[#This Row],[Competência]]=""),"",MONTH(IF(tbLancamentos[[#This Row],[Competência]]<>"",tbLancamentos[[#This Row],[Competência]],tbLancamentos[[#This Row],[Data]]))) | S29: =IF(AND(tbLancamentos[[#This Row],[Data]]="",tbLancamentos[[#This Row],[Competência]]=""),"",YEAR(IF(tbLancamentos[[#This Row],[Competência]]<>"",tbLancamentos[[#This Row],[Competência]],tbLancamentos[[#This Row],[Data]]))) | T29: =IF(tbLancamentos[[#This Row],[Valor]]="","",IF(AND(tbLancamentos[[#This Row],[Tipo]]<>"Investimento",OR(tbLancamentos[[#This Row],[Situação]]="",tbLancamentos[[#This Row],[Situação]]="Pago",tbLancamentos[[#This Row],[Situação]]="Recebido",tbLancamentos[[#This Row],[Situação]]="Descontar Depois")),"sim","não"))
B30: 46178 | C30: Salário — titular | D30: 7800 | E30: Receita | F30: Salário | G30: Recebido | J30: Conta corrente Itaú | K30: Transferência | O30: Mensal | Q30: EXEMPLO | R30: =IF(AND(tbLancamentos[[#This Row],[Data]]="",tbLancamentos[[#This Row],[Competência]]=""),"",MONTH(IF(tbLancamentos[[#This Row],[Competência]]<>"",tbLancamentos[[#This Row],[Competência]],tbLancamentos[[#This Row],[Data]]))) | S30: =IF(AND(tbLancamentos[[#This Row],[Data]]="",tbLancamentos[[#This Row],[Competência]]=""),"",YEAR(IF(tbLancamentos[[#This Row],[Competência]]<>"",tbLancamentos[[#This Row],[Competência]],tbLancamentos[[#This Row],[Data]]))) | T30: =IF(tbLancamentos[[#This Row],[Valor]]="","",IF(AND(tbLancamentos[[#This Row],[Tipo]]<>"Investimento",OR(tbLancamentos[[#This Row],[Situação]]="",tbLancamentos[[#This Row],[Situação]]="Pago",tbLancamentos[[#This Row],[Situação]]="Recebido",tbLancamentos[[#This Row],[Situação]]="Descontar Depois")),"sim","não"))
B31: 46178 | C31: Salário — cônjuge | D31: 5200 | E31: Receita | F31: Salário | G31: Recebido | J31: Conta Nubank | K31: Transferência | O31: Mensal | Q31: EXEMPLO | R31: =IF(AND(tbLancamentos[[#This Row],[Data]]="",tbLancamentos[[#This Row],[Competência]]=""),"",MONTH(IF(tbLancamentos[[#This Row],[Competência]]<>"",tbLancamentos[[#This Row],[Competência]],tbLancamentos[[#This Row],[Data]]))) | S31: =IF(AND(tbLancamentos[[#This Row],[Data]]="",tbLancamentos[[#This Row],[Competência]]=""),"",YEAR(IF(tbLancamentos[[#This Row],[Competência]]<>"",tbLancamentos[[#This Row],[Competência]],tbLancamentos[[#This Row],[Data]]))) | T31: =IF(tbLancamentos[[#This Row],[Valor]]="","",IF(AND(tbLancamentos[[#This Row],[Tipo]]<>"Investimento",OR(tbLancamentos[[#This Row],[Situação]]="",tbLancamentos[[#This Row],[Situação]]="Pago",tbLancamentos[[#This Row],[Situação]]="Recebido",tbLancamentos[[#This Row],[Situação]]="Descontar Depois")),"sim","não"))
B32: 46180 | C32: Mercado do mês | D32: 788.45 | E32: Despesa | F32: Alimentação | G32: Pago | H32: Essenciais | J32: Cartão Nubank | K32: Cartão de crédito | O32: Mercado | Q32: EXEMPLO | R32: =IF(AND(tbLancamentos[[#This Row],[Data]]="",tbLancamentos[[#This Row],[Competência]]=""),"",MONTH(IF(tbLancamentos[[#This Row],[Competência]]<>"",tbLancamentos[[#This Row],[Competência]],tbLancamentos[[#This Row],[Data]]))) | S32: =IF(AND(tbLancamentos[[#This Row],[Data]]="",tbLancamentos[[#This Row],[Competência]]=""),"",YEAR(IF(tbLancamentos[[#This Row],[Competência]]<>"",tbLancamentos[[#This Row],[Competência]],tbLancamentos[[#This Row],[Data]]))) | T32: =IF(tbLancamentos[[#This Row],[Valor]]="","",IF(AND(tbLancamentos[[#This Row],[Tipo]]<>"Investimento",OR(tbLancamentos[[#This Row],[Situação]]="",tbLancamentos[[#This Row],[Situação]]="Pago",tbLancamentos[[#This Row],[Situação]]="Recebido",tbLancamentos[[#This Row],[Situação]]="Descontar Depois")),"sim","não"))
B33: 46181 | C33: Mensalidade escolar | D33: 1450 | E33: Despesa | F33: Educação | G33: Pago | H33: Essenciais | J33: Conta corrente Itaú | K33: Boleto | O33: Escola | Q33: EXEMPLO | R33: =IF(AND(tbLancamentos[[#This Row],[Data]]="",tbLancamentos[[#This Row],[Competência]]=""),"",MONTH(IF(tbLancamentos[[#This Row],[Competência]]<>"",tbLancamentos[[#This Row],[Competência]],tbLancamentos[[#This Row],[Data]]))) | S33: =IF(AND(tbLancamentos[[#This Row],[Data]]="",tbLancamentos[[#This Row],[Competência]]=""),"",YEAR(IF(tbLancamentos[[#This Row],[Competência]]<>"",tbLancamentos[[#This Row],[Competência]],tbLancamentos[[#This Row],[Data]]))) | T33: =IF(tbLancamentos[[#This Row],[Valor]]="","",IF(AND(tbLancamentos[[#This Row],[Tipo]]<>"Investimento",OR(tbLancamentos[[#This Row],[Situação]]="",tbLancamentos[[#This Row],[Situação]]="Pago",tbLancamentos[[#This Row],[Situação]]="Recebido",tbLancamentos[[#This Row],[Situação]]="Descontar Depois")),"sim","não"))
B34: 46183 | C34: Aluguel do apartamento | D34: 2350 | E34: Despesa | F34: Moradia | G34: Pago | H34: Essenciais | J34: Conta corrente Itaú | K34: Boleto | O34: Aluguel/Financiamento | Q34: EXEMPLO | R34: =IF(AND(tbLancamentos[[#This Row],[Data]]="",tbLancamentos[[#This Row],[Competência]]=""),"",MONTH(IF(tbLancamentos[[#This Row],[Competência]]<>"",tbLancamentos[[#This Row],[Competência]],tbLancamentos[[#This Row],[Data]]))) | S34: =IF(AND(tbLancamentos[[#This Row],[Data]]="",tbLancamentos[[#This Row],[Competência]]=""),"",YEAR(IF(tbLancamentos[[#This Row],[Competência]]<>"",tbLancamentos[[#This Row],[Competência]],tbLancamentos[[#This Row],[Data]]))) | T34: =IF(tbLancamentos[[#This Row],[Valor]]="","",IF(AND(tbLancamentos[[#This Row],[Tipo]]<>"Investimento",OR(tbLancamentos[[#This Row],[Situação]]="",tbLancamentos[[#This Row],[Situação]]="Pago",tbLancamentos[[#This Row],[Situação]]="Recebido",tbLancamentos[[#This Row],[Situação]]="Descontar Depois")),"sim","não"))
B35: 46183 | C35: Conta de energia | D35: 274.8 | E35: Despesa | F35: Contas da casa | G35: Pago | H35: Essenciais | J35: Conta corrente Itaú | K35: Débito automático | O35: Energia | Q35: EXEMPLO | R35: =IF(AND(tbLancamentos[[#This Row],[Data]]="",tbLancamentos[[#This Row],[Competência]]=""),"",MONTH(IF(tbLancamentos[[#This Row],[Competência]]<>"",tbLancamentos[[#This Row],[Competência]],tbLancamentos[[#This Row],[Data]]))) | S35: =IF(AND(tbLancamentos[[#This Row],[Data]]="",tbLancamentos[[#This Row],[Competência]]=""),"",YEAR(IF(tbLancamentos[[#This Row],[Competência]]<>"",tbLancamentos[[#This Row],[Competência]],tbLancamentos[[#This Row],[Data]]))) | T35: =IF(tbLancamentos[[#This Row],[Valor]]="","",IF(AND(tbLancamentos[[#This Row],[Tipo]]<>"Investimento",OR(tbLancamentos[[#This Row],[Situação]]="",tbLancamentos[[#This Row],[Situação]]="Pago",tbLancamentos[[#This Row],[Situação]]="Recebido",tbLancamentos[[#This Row],[Situação]]="Descontar Depois")),"sim","não"))
B36: 46185 | C36: Streaming + academia | D36: 174.8 | E36: Despesa | F36: Assinaturas | G36: Pago | H36: Essenciais | J36: Cartão Nubank | K36: Cartão de crédito | O36: Streaming | Q36: EXEMPLO | R36: =IF(AND(tbLancamentos[[#This Row],[Data]]="",tbLancamentos[[#This Row],[Competência]]=""),"",MONTH(IF(tbLancamentos[[#This Row],[Competência]]<>"",tbLancamentos[[#This Row],[Competência]],tbLancamentos[[#This Row],[Data]]))) | S36: =IF(AND(tbLancamentos[[#This Row],[Data]]="",tbLancamentos[[#This Row],[Competência]]=""),"",YEAR(IF(tbLancamentos[[#This Row],[Competência]]<>"",tbLancamentos[[#This Row],[Competência]],tbLancamentos[[#This Row],[Data]]))) | T36: =IF(tbLancamentos[[#This Row],[Valor]]="","",IF(AND(tbLancamentos[[#This Row],[Tipo]]<>"Investimento",OR(tbLancamentos[[#This Row],[Situação]]="",tbLancamentos[[#This Row],[Situação]]="Pago",tbLancamentos[[#This Row],[Situação]]="Recebido",tbLancamentos[[#This Row],[Situação]]="Descontar Depois")),"sim","não"))
B37: 46187 | C37: Festa junina da escola | D37: 95 | E37: Despesa | F37: Lazer | G37: Pago | H37: Lazer | J37: Carteira | K37: Dinheiro | O37: Passeios | Q37: EXEMPLO | R37: =IF(AND(tbLancamentos[[#This Row],[Data]]="",tbLancamentos[[#This Row],[Competência]]=""),"",MONTH(IF(tbLancamentos[[#This Row],[Competência]]<>"",tbLancamentos[[#This Row],[Competência]],tbLancamentos[[#This Row],[Data]]))) | S37: =IF(AND(tbLancamentos[[#This Row],[Data]]="",tbLancamentos[[#This Row],[Competência]]=""),"",YEAR(IF(tbLancamentos[[#This Row],[Competência]]<>"",tbLancamentos[[#This Row],[Competência]],tbLancamentos[[#This Row],[Data]]))) | T37: =IF(tbLancamentos[[#This Row],[Valor]]="","",IF(AND(tbLancamentos[[#This Row],[Tipo]]<>"Investimento",OR(tbLancamentos[[#This Row],[Situação]]="",tbLancamentos[[#This Row],[Situação]]="Pago",tbLancamentos[[#This Row],[Situação]]="Recebido",tbLancamentos[[#This Row],[Situação]]="Descontar Depois")),"sim","não"))
B38: 46188 | C38: Combustível | D38: 342.1 | E38: Despesa | F38: Transporte | G38: Pago | H38: Essenciais | J38: Cartão Itaú | K38: Cartão de crédito | O38: Combustível | Q38: EXEMPLO | R38: =IF(AND(tbLancamentos[[#This Row],[Data]]="",tbLancamentos[[#This Row],[Competência]]=""),"",MONTH(IF(tbLancamentos[[#This Row],[Competência]]<>"",tbLancamentos[[#This Row],[Competência]],tbLancamentos[[#This Row],[Data]]))) | S38: =IF(AND(tbLancamentos[[#This Row],[Data]]="",tbLancamentos[[#This Row],[Competência]]=""),"",YEAR(IF(tbLancamentos[[#This Row],[Competência]]<>"",tbLancamentos[[#This Row],[Competência]],tbLancamentos[[#This Row],[Data]]))) | T38: =IF(tbLancamentos[[#This Row],[Valor]]="","",IF(AND(tbLancamentos[[#This Row],[Tipo]]<>"Investimento",OR(tbLancamentos[[#This Row],[Situação]]="",tbLancamentos[[#This Row],[Situação]]="Pago",tbLancamentos[[#This Row],[Situação]]="Recebido",tbLancamentos[[#This Row],[Situação]]="Descontar Depois")),"sim","não"))
B39: 46194 | C39: Revisão do carro | D39: 780 | E39: Despesa | F39: Transporte | G39: Pago | H39: Essenciais | J39: Cartão Itaú | K39: Cartão de crédito | O39: Manutenção do carro | Q39: EXEMPLO | R39: =IF(AND(tbLancamentos[[#This Row],[Data]]="",tbLancamentos[[#This Row],[Competência]]=""),"",MONTH(IF(tbLancamentos[[#This Row],[Competência]]<>"",tbLancamentos[[#This Row],[Competência]],tbLancamentos[[#This Row],[Data]]))) | S39: =IF(AND(tbLancamentos[[#This Row],[Data]]="",tbLancamentos[[#This Row],[Competência]]=""),"",YEAR(IF(tbLancamentos[[#This Row],[Competência]]<>"",tbLancamentos[[#This Row],[Competência]],tbLancamentos[[#This Row],[Data]]))) | T39: =IF(tbLancamentos[[#This Row],[Valor]]="","",IF(AND(tbLancamentos[[#This Row],[Tipo]]<>"Investimento",OR(tbLancamentos[[#This Row],[Situação]]="",tbLancamentos[[#This Row],[Situação]]="Pago",tbLancamentos[[#This Row],[Situação]]="Recebido",tbLancamentos[[#This Row],[Situação]]="Descontar Depois")),"sim","não"))
B40: 46200 | C40: Cinema / passeio | D40: 72.5 | E40: Despesa | F40: Lazer | G40: Pago | H40: Lazer | J40: Conta Nubank | K40: PIX | O40: Cinema | Q40: EXEMPLO | R40: =IF(AND(tbLancamentos[[#This Row],[Data]]="",tbLancamentos[[#This Row],[Competência]]=""),"",MONTH(IF(tbLancamentos[[#This Row],[Competência]]<>"",tbLancamentos[[#This Row],[Competência]],tbLancamentos[[#This Row],[Data]]))) | S40: =IF(AND(tbLancamentos[[#This Row],[Data]]="",tbLancamentos[[#This Row],[Competência]]=""),"",YEAR(IF(tbLancamentos[[#This Row],[Competência]]<>"",tbLancamentos[[#This Row],[Competência]],tbLancamentos[[#This Row],[Data]]))) | T40: =IF(tbLancamentos[[#This Row],[Valor]]="","",IF(AND(tbLancamentos[[#This Row],[Tipo]]<>"Investimento",OR(tbLancamentos[[#This Row],[Situação]]="",tbLancamentos[[#This Row],[Situação]]="Pago",tbLancamentos[[#This Row],[Situação]]="Recebido",tbLancamentos[[#This Row],[Situação]]="Descontar Depois")),"sim","não"))
B41: 46206 | C41: Plano de saúde familiar | D41: 890 | E41: Despesa | F41: Saúde | G41: Pago | H41: Essenciais | J41: Conta corrente Itaú | K41: Débito automático | O41: Plano de saúde | Q41: EXEMPLO | R41: =IF(AND(tbLancamentos[[#This Row],[Data]]="",tbLancamentos[[#This Row],[Competência]]=""),"",MONTH(IF(tbLancamentos[[#This Row],[Competência]]<>"",tbLancamentos[[#This Row],[Competência]],tbLancamentos[[#This Row],[Data]]))) | S41: =IF(AND(tbLancamentos[[#This Row],[Data]]="",tbLancamentos[[#This Row],[Competência]]=""),"",YEAR(IF(tbLancamentos[[#This Row],[Competência]]<>"",tbLancamentos[[#This Row],[Competência]],tbLancamentos[[#This Row],[Data]]))) | T41: =IF(tbLancamentos[[#This Row],[Valor]]="","",IF(AND(tbLancamentos[[#This Row],[Tipo]]<>"Investimento",OR(tbLancamentos[[#This Row],[Situação]]="",tbLancamentos[[#This Row],[Situação]]="Pago",tbLancamentos[[#This Row],[Situação]]="Recebido",tbLancamentos[[#This Row],[Situação]]="Descontar Depois")),"sim","não"))
...

Sheet ContasMes
B2: Contas do mês | E2: ="Mês: "&MesSelecionado&" / "&AnoSelecionado | I2: =HYPERLINK("#Inicio!A1","⌂ Início")
B3: Checklist das contas e receitas recorrentes (marcadas em Favoritos). O status vem dos lançamentos do mês escolhido no Dashboard.
M4: BLOCO PRONTO PARA COLAR — só as contas que faltam lançar
B5: CONTAS LANÇADAS | E5: PREVISTO | F5: JÁ LANÇADO | G5: FALTA LANÇAR (PREVISTO) | M5: 1. Selecione as linhas preenchidas do bloco abaixo e copie (Ctrl+C). | S5: =HYPERLINK("#Lancamentos!B"&(ROWS(tbLancamentos[Data])+5),"✚ Ir para a primeira linha vazia")
B6: =SUMPRODUCT(--(I10:I34>0))&" de "&SUMPRODUCT(--(LEN(B10:B34)>0)) | E6: =SUM(E10:E34) | F6: =SUM(F10:F34) | G6: =SUMPRODUCT((LEFT(G10:G34,1)="✖")*N(+E10:E34)) | M6: 2. Clique no botão ao lado para ir à primeira linha vazia de Lançamentos.
M7: 3. Cole só os valores: Ctrl+Shift+V (ou Ctrl+Alt+V ➜ Valores).
M8: 4. Elas entram como Pendente: troque para Pago quando pagar.
B9: Conta / receita | C9: Categoria | D9: Dia | E9: Previsto | F9: Lançado no mês | G9: Status | H9: Linha | I9: Lançamentos | J9: Pendentes | K9: Falta nº | M9: Data | N9: Descrição | O9: Valor | P9: Tipo | Q9: Categoria | R9: Situação | S9: Pote | T9: Quem | U9: Conta | V9: Forma de pagamento | W9: Parcela
B10: =IF($H10=0,"",INDEX(Atalhos!$B:$B,$H10)&"") | C10: =IF($H10=0,"",INDEX(Atalhos!$D:$D,$H10)&"") | D10: =IF($H10=0,"",IF(INDEX(Atalhos!$K:$K,$H10)="","",INDEX(Atalhos!$K:$K,$H10))) | E10: =IF(B10="","",IF(N(INDEX(Atalhos!$I:$I,$H10))>0,INDEX(Atalhos!$I:$I,$H10),SUMIFS(tbLancamentos[Valor],tbLancamentos[Descrição],B10,tbLancamentos[Mês],Calc!$B$6,tbLancamentos[Ano],Calc!$B$7))) | F10: =IF(B10="","",SUMIFS(tbLancamentos[Valor],tbLancamentos[Descrição],B10,tbLancamentos[Mês],MesNum,tbLancamentos[Ano],AnoSelecionado)) | G10: =IF(B10="","",IF(I10=0,IF(AND(D10<>"",DATE(AnoSelecionado,MesNum,MIN(IF(D10="",1,D10),DAY(EOMONTH(DATE(AnoSelecionado,MesNum,1),0))))<TODAY()),"✖ Atrasada — falta lançar","✖ Falta lançar"),IF(J10>0,IF(DATE(AnoSelecionado,MesNum,MIN(IF(D10="",1,D10),DAY(EOMONTH(DATE(AnoSelecionado,MesNum,1),0))))<TODAY(),"⏳ Pendente — vencida","⏳ Pendente"),IF(INDEX(Atalhos!$C:$C,$H10)="Receita","✔ Recebido","✔ Pago")))) | H10: =Calc!AR2 | I10: =IF(B10="",0,COUNTIFS(tbLancamentos[Descrição],B10,tbLancamentos[Mês],MesNum,tbLancamentos[Ano],AnoSelecionado)) | J10: =IF(B10="",0,COUNTIFS(tbLancamentos[Descrição],B10,tbLancamentos[Mês],MesNum,tbLancamentos[Ano],AnoSelecionado,tbLancamentos[Situação],"Pendente")) | K10: =IF(LEFT(G10,1)="✖",SUMPRODUCT(--(LEFT($G$10:G10,1)="✖")),0) | M10: =IFERROR(DATE(AnoSelecionado,MesNum,MIN(IF(INDEX($D$10:$D$34,MATCH(1,$K$10:$K$34,0))="",1,INDEX($D$10:$D$34,MATCH(1,$K$10:$K$34,0))),DAY(EOMONTH(DATE(AnoSelecionado,MesNum,1),0)))),"") | N10: =IFERROR(INDEX($B$10:$B$34,MATCH(1,$K$10:$K$34,0)),"") | O10: =IFERROR(IF(N(INDEX($E$10:$E$34,MATCH(1,$K$10:$K$34,0)))>0,INDEX($E$10:$E$34,MATCH(1,$K$10:$K$34,0)),""),"") | P10: =IFERROR(INDEX(Atalhos!$C:$C,INDEX($H$10:$H$34,MATCH(1,$K$10:$K$34,0)))&"","") | Q10: =IFERROR(INDEX(Atalhos!$D:$D,INDEX($H$10:$H$34,MATCH(1,$K$10:$K$34,0)))&"","") | R10: =IFERROR(IF(MATCH(1,$K$10:$K$34,0)>0,"Pendente",""),"") | S10: =IFERROR(INDEX(Atalhos!$E:$E,INDEX($H$10:$H$34,MATCH(1,$K$10:$K$34,0)))&"","") | T10: =IFERROR(INDEX(Atalhos!$F:$F,INDEX($H$10:$H$34,MATCH(1,$K$10:$K$34,0)))&"","") | U10: =IFERROR(INDEX(Atalhos!$G:$G,INDEX($H$10:$H$34,MATCH(1,$K$10:$K$34,0)))&"","") | V10: =IFERROR(INDEX(Atalhos!$H:$H,INDEX($H$10:$H$34,MATCH(1,$K$10:$K$34,0)))&"","") | W10: =""
B11: =IF($H11=0,"",INDEX(Atalhos!$B:$B,$H11)&"") | C11: =IF($H11=0,"",INDEX(Atalhos!$D:$D,$H11)&"") | D11: =IF($H11=0,"",IF(INDEX(Atalhos!$K:$K,$H11)="","",INDEX(Atalhos!$K:$K,$H11))) | E11: =IF(B11="","",IF(N(INDEX(Atalhos!$I:$I,$H11))>0,INDEX(Atalhos!$I:$I,$H11),SUMIFS(tbLancamentos[Valor],tbLancamentos[Descrição],B11,tbLancamentos[Mês],Calc!$B$6,tbLancamentos[Ano],Calc!$B$7))) | F11: =IF(B11="","",SUMIFS(tbLancamentos[Valor],tbLancamentos[Descrição],B11,tbLancamentos[Mês],MesNum,tbLancamentos[Ano],AnoSelecionado)) | G11: =IF(B11="","",IF(I11=0,IF(AND(D11<>"",DATE(AnoSelecionado,MesNum,MIN(IF(D11="",1,D11),DAY(EOMONTH(DATE(AnoSelecionado,MesNum,1),0))))<TODAY()),"✖ Atrasada — falta lançar","✖ Falta lançar"),IF(J11>0,IF(DATE(AnoSelecionado,MesNum,MIN(IF(D11="",1,D11),DAY(EOMONTH(DATE(AnoSelecionado,MesNum,1),0))))<TODAY(),"⏳ Pendente — vencida","⏳ Pendente"),IF(INDEX(Atalhos!$C:$C,$H11)="Receita","✔ Recebido","✔ Pago")))) | H11: =Calc!AR3 | I11: =IF(B11="",0,COUNTIFS(tbLancamentos[Descrição],B11,tbLancamentos[Mês],MesNum,tbLancamentos[Ano],AnoSelecionado)) | J11: =IF(B11="",0,COUNTIFS(tbLancamentos[Descrição],B11,tbLancamentos[Mês],MesNum,tbLancamentos[Ano],AnoSelecionado,tbLancamentos[Situação],"Pendente")) | K11: =IF(LEFT(G11,1)="✖",SUMPRODUCT(--(LEFT($G$10:G11,1)="✖")),0) | M11: =IFERROR(DATE(AnoSelecionado,MesNum,MIN(IF(INDEX($D$10:$D$34,MATCH(2,$K$10:$K$34,0))="",1,INDEX($D$10:$D$34,MATCH(2,$K$10:$K$34,0))),DAY(EOMONTH(DATE(AnoSelecionado,MesNum,1),0)))),"") | N11: =IFERROR(INDEX($B$10:$B$34,MATCH(2,$K$10:$K$34,0)),"") | O11: =IFERROR(IF(N(INDEX($E$10:$E$34,MATCH(2,$K$10:$K$34,0)))>0,INDEX($E$10:$E$34,MATCH(2,$K$10:$K$34,0)),""),"") | P11: =IFERROR(INDEX(Atalhos!$C:$C,INDEX($H$10:$H$34,MATCH(2,$K$10:$K$34,0)))&"","") | Q11: =IFERROR(INDEX(Atalhos!$D:$D,INDEX($H$10:$H$34,MATCH(2,$K$10:$K$34,0)))&"","") | R11: =IFERROR(IF(MATCH(2,$K$10:$K$34,0)>0,"Pendente",""),"") | S11: =IFERROR(INDEX(Atalhos!$E:$E,INDEX($H$10:$H$34,MATCH(2,$K$10:$K$34,0)))&"","") | T11: =IFERROR(INDEX(Atalhos!$F:$F,INDEX($H$10:$H$34,MATCH(2,$K$10:$K$34,0)))&"","") | U11: =IFERROR(INDEX(Atalhos!$G:$G,INDEX($H$10:$H$34,MATCH(2,$K$10:$K$34,0)))&"","") | V11: =IFERROR(INDEX(Atalhos!$H:$H,INDEX($H$10:$H$34,MATCH(2,$K$10:$K$34,0)))&"","") | W11: =""
B12: =IF($H12=0,"",INDEX(Atalhos!$B:$B,$H12)&"") | C12: =IF($H12=0,"",INDEX(Atalhos!$D:$D,$H12)&"") | D12: =IF($H12=0,"",IF(INDEX(Atalhos!$K:$K,$H12)="","",INDEX(Atalhos!$K:$K,$H12))) | E12: =IF(B12="","",IF(N(INDEX(Atalhos!$I:$I,$H12))>0,INDEX(Atalhos!$I:$I,$H12),SUMIFS(tbLancamentos[Valor],tbLancamentos[Descrição],B12,tbLancamentos[Mês],Calc!$B$6,tbLancamentos[Ano],Calc!$B$7))) | F12: =IF(B12="","",SUMIFS(tbLancamentos[Valor],tbLancamentos[Descrição],B12,tbLancamentos[Mês],MesNum,tbLancamentos[Ano],AnoSelecionado)) | G12: =IF(B12="","",IF(I12=0,IF(AND(D12<>"",DATE(AnoSelecionado,MesNum,MIN(IF(D12="",1,D12),DAY(EOMONTH(DATE(AnoSelecionado,MesNum,1),0))))<TODAY()),"✖ Atrasada — falta lançar","✖ Falta lançar"),IF(J12>0,IF(DATE(AnoSelecionado,MesNum,MIN(IF(D12="",1,D12),DAY(EOMONTH(DATE(AnoSelecionado,MesNum,1),0))))<TODAY(),"⏳ Pendente — vencida","⏳ Pendente"),IF(INDEX(Atalhos!$C:$C,$H12)="Receita","✔ Recebido","✔ Pago")))) | H12: =Calc!AR4 | I12: =IF(B12="",0,COUNTIFS(tbLancamentos[Descrição],B12,tbLancamentos[Mês],MesNum,tbLancamentos[Ano],AnoSelecionado)) | J12: =IF(B12="",0,COUNTIFS(tbLancamentos[Descrição],B12,tbLancamentos[Mês],MesNum,tbLancamentos[Ano],AnoSelecionado,tbLancamentos[Situação],"Pendente")) | K12: =IF(LEFT(G12,1)="✖",SUMPRODUCT(--(LEFT($G$10:G12,1)="✖")),0) | M12: =IFERROR(DATE(AnoSelecionado,MesNum,MIN(IF(INDEX($D$10:$D$34,MATCH(3,$K$10:$K$34,0))="",1,INDEX($D$10:$D$34,MATCH(3,$K$10:$K$34,0))),DAY(EOMONTH(DATE(AnoSelecionado,MesNum,1),0)))),"") | N12: =IFERROR(INDEX($B$10:$B$34,MATCH(3,$K$10:$K$34,0)),"") | O12: =IFERROR(IF(N(INDEX($E$10:$E$34,MATCH(3,$K$10:$K$34,0)))>0,INDEX($E$10:$E$34,MATCH(3,$K$10:$K$34,0)),""),"") | P12: =IFERROR(INDEX(Atalhos!$C:$C,INDEX($H$10:$H$34,MATCH(3,$K$10:$K$34,0)))&"","") | Q12: =IFERROR(INDEX(Atalhos!$D:$D,INDEX($H$10:$H$34,MATCH(3,$K$10:$K$34,0)))&"","") | R12: =IFERROR(IF(MATCH(3,$K$10:$K$34,0)>0,"Pendente",""),"") | S12: =IFERROR(INDEX(Atalhos!$E:$E,INDEX($H$10:$H$34,MATCH(3,$K$10:$K$34,0)))&"","") | T12: =IFERROR(INDEX(Atalhos!$F:$F,INDEX($H$10:$H$34,MATCH(3,$K$10:$K$34,0)))&"","") | U12: =IFERROR(INDEX(Atalhos!$G:$G,INDEX($H$10:$H$34,MATCH(3,$K$10:$K$34,0)))&"","") | V12: =IFERROR(INDEX(Atalhos!$H:$H,INDEX($H$10:$H$34,MATCH(3,$K$10:$K$34,0)))&"","") | W12: =""
B13: =IF($H13=0,"",INDEX(Atalhos!$B:$B,$H13)&"") | C13: =IF($H13=0,"",INDEX(Atalhos!$D:$D,$H13)&"") | D13: =IF($H13=0,"",IF(INDEX(Atalhos!$K:$K,$H13)="","",INDEX(Atalhos!$K:$K,$H13))) | E13: =IF(B13="","",IF(N(INDEX(Atalhos!$I:$I,$H13))>0,INDEX(Atalhos!$I:$I,$H13),SUMIFS(tbLancamentos[Valor],tbLancamentos[Descrição],B13,tbLancamentos[Mês],Calc!$B$6,tbLancamentos[Ano],Calc!$B$7))) | F13: =IF(B13="","",SUMIFS(tbLancamentos[Valor],tbLancamentos[Descrição],B13,tbLancamentos[Mês],MesNum,tbLancamentos[Ano],AnoSelecionado)) | G13: =IF(B13="","",IF(I13=0,IF(AND(D13<>"",DATE(AnoSelecionado,MesNum,MIN(IF(D13="",1,D13),DAY(EOMONTH(DATE(AnoSelecionado,MesNum,1),0))))<TODAY()),"✖ Atrasada — falta lançar","✖ Falta lançar"),IF(J13>0,IF(DATE(AnoSelecionado,MesNum,MIN(IF(D13="",1,D13),DAY(EOMONTH(DATE(AnoSelecionado,MesNum,1),0))))<TODAY(),"⏳ Pendente — vencida","⏳ Pendente"),IF(INDEX(Atalhos!$C:$C,$H13)="Receita","✔ Recebido","✔ Pago")))) | H13: =Calc!AR5 | I13: =IF(B13="",0,COUNTIFS(tbLancamentos[Descrição],B13,tbLancamentos[Mês],MesNum,tbLancamentos[Ano],AnoSelecionado)) | J13: =IF(B13="",0,COUNTIFS(tbLancamentos[Descrição],B13,tbLancamentos[Mês],MesNum,tbLancamentos[Ano],AnoSelecionado,tbLancamentos[Situação],"Pendente")) | K13: =IF(LEFT(G13,1)="✖",SUMPRODUCT(--(LEFT($G$10:G13,1)="✖")),0) | M13: =IFERROR(DATE(AnoSelecionado,MesNum,MIN(IF(INDEX($D$10:$D$34,MATCH(4,$K$10:$K$34,0))="",1,INDEX($D$10:$D$34,MATCH(4,$K$10:$K$34,0))),DAY(EOMONTH(DATE(AnoSelecionado,MesNum,1),0)))),"") | N13: =IFERROR(INDEX($B$10:$B$34,MATCH(4,$K$10:$K$34,0)),"") | O13: =IFERROR(IF(N(INDEX($E$10:$E$34,MATCH(4,$K$10:$K$34,0)))>0,INDEX($E$10:$E$34,MATCH(4,$K$10:$K$34,0)),""),"") | P13: =IFERROR(INDEX(Atalhos!$C:$C,INDEX($H$10:$H$34,MATCH(4,$K$10:$K$34,0)))&"","") | Q13: =IFERROR(INDEX(Atalhos!$D:$D,INDEX($H$10:$H$34,MATCH(4,$K$10:$K$34,0)))&"","") | R13: =IFERROR(IF(MATCH(4,$K$10:$K$34,0)>0,"Pendente",""),"") | S13: =IFERROR(INDEX(Atalhos!$E:$E,INDEX($H$10:$H$34,MATCH(4,$K$10:$K$34,0)))&"","") | T13: =IFERROR(INDEX(Atalhos!$F:$F,INDEX($H$10:$H$34,MATCH(4,$K$10:$K$34,0)))&"","") | U13: =IFERROR(INDEX(Atalhos!$G:$G,INDEX($H$10:$H$34,MATCH(4,$K$10:$K$34,0)))&"","") | V13: =IFERROR(INDEX(Atalhos!$H:$H,INDEX($H$10:$H$34,MATCH(4,$K$10:$K$34,0)))&"","") | W13: =""
B14: =IF($H14=0,"",INDEX(Atalhos!$B:$B,$H14)&"") | C14: =IF($H14=0,"",INDEX(Atalhos!$D:$D,$H14)&"") | D14: =IF($H14=0,"",IF(INDEX(Atalhos!$K:$K,$H14)="","",INDEX(Atalhos!$K:$K,$H14))) | E14: =IF(B14="","",IF(N(INDEX(Atalhos!$I:$I,$H14))>0,INDEX(Atalhos!$I:$I,$H14),SUMIFS(tbLancamentos[Valor],tbLancamentos[Descrição],B14,tbLancamentos[Mês],Calc!$B$6,tbLancamentos[Ano],Calc!$B$7))) | F14: =IF(B14="","",SUMIFS(tbLancamentos[Valor],tbLancamentos[Descrição],B14,tbLancamentos[Mês],MesNum,tbLancamentos[Ano],AnoSelecionado)) | G14: =IF(B14="","",IF(I14=0,IF(AND(D14<>"",DATE(AnoSelecionado,MesNum,MIN(IF(D14="",1,D14),DAY(EOMONTH(DATE(AnoSelecionado,MesNum,1),0))))<TODAY()),"✖ Atrasada — falta lançar","✖ Falta lançar"),IF(J14>0,IF(DATE(AnoSelecionado,MesNum,MIN(IF(D14="",1,D14),DAY(EOMONTH(DATE(AnoSelecionado,MesNum,1),0))))<TODAY(),"⏳ Pendente — vencida","⏳ Pendente"),IF(INDEX(Atalhos!$C:$C,$H14)="Receita","✔ Recebido","✔ Pago")))) | H14: =Calc!AR6 | I14: =IF(B14="",0,COUNTIFS(tbLancamentos[Descrição],B14,tbLancamentos[Mês],MesNum,tbLancamentos[Ano],AnoSelecionado)) | J14: =IF(B14="",0,COUNTIFS(tbLancamentos[Descrição],B14,tbLancamentos[Mês],MesNum,tbLancamentos[Ano],AnoSelecionado,tbLancamentos[Situação],"Pendente")) | K14: =IF(LEFT(G14,1)="✖",SUMPRODUCT(--(LEFT($G$10:G14,1)="✖")),0) | M14: =IFERROR(DATE(AnoSelecionado,MesNum,MIN(IF(INDEX($D$10:$D$34,MATCH(5,$K$10:$K$34,0))="",1,INDEX($D$10:$D$34,MATCH(5,$K$10:$K$34,0))),DAY(EOMONTH(DATE(AnoSelecionado,MesNum,1),0)))),"") | N14: =IFERROR(INDEX($B$10:$B$34,MATCH(5,$K$10:$K$34,0)),"") | O14: =IFERROR(IF(N(INDEX($E$10:$E$34,MATCH(5,$K$10:$K$34,0)))>0,INDEX($E$10:$E$34,MATCH(5,$K$10:$K$34,0)),""),"") | P14: =IFERROR(INDEX(Atalhos!$C:$C,INDEX($H$10:$H$34,MATCH(5,$K$10:$K$34,0)))&"","") | Q14: =IFERROR(INDEX(Atalhos!$D:$D,INDEX($H$10:$H$34,MATCH(5,$K$10:$K$34,0)))&"","") | R14: =IFERROR(IF(MATCH(5,$K$10:$K$34,0)>0,"Pendente",""),"") | S14: =IFERROR(INDEX(Atalhos!$E:$E,INDEX($H$10:$H$34,MATCH(5,$K$10:$K$34,0)))&"","") | T14: =IFERROR(INDEX(Atalhos!$F:$F,INDEX($H$10:$H$34,MATCH(5,$K$10:$K$34,0)))&"","") | U14: =IFERROR(INDEX(Atalhos!$G:$G,INDEX($H$10:$H$34,MATCH(5,$K$10:$K$34,0)))&"","") | V14: =IFERROR(INDEX(Atalhos!$H:$H,INDEX($H$10:$H$34,MATCH(5,$K$10:$K$34,0)))&"","") | W14: =""
B15: =IF($H15=0,"",INDEX(Atalhos!$B:$B,$H15)&"") | C15: =IF($H15=0,"",INDEX(Atalhos!$D:$D,$H15)&"") | D15: =IF($H15=0,"",IF(INDEX(Atalhos!$K:$K,$H15)="","",INDEX(Atalhos!$K:$K,$H15))) | E15: =IF(B15="","",IF(N(INDEX(Atalhos!$I:$I,$H15))>0,INDEX(Atalhos!$I:$I,$H15),SUMIFS(tbLancamentos[Valor],tbLancamentos[Descrição],B15,tbLancamentos[Mês],Calc!$B$6,tbLancamentos[Ano],Calc!$B$7))) | F15: =IF(B15="","",SUMIFS(tbLancamentos[Valor],tbLancamentos[Descrição],B15,tbLancamentos[Mês],MesNum,tbLancamentos[Ano],AnoSelecionado)) | G15: =IF(B15="","",IF(I15=0,IF(AND(D15<>"",DATE(AnoSelecionado,MesNum,MIN(IF(D15="",1,D15),DAY(EOMONTH(DATE(AnoSelecionado,MesNum,1),0))))<TODAY()),"✖ Atrasada — falta lançar","✖ Falta lançar"),IF(J15>0,IF(DATE(AnoSelecionado,MesNum,MIN(IF(D15="",1,D15),DAY(EOMONTH(DATE(AnoSelecionado,MesNum,1),0))))<TODAY(),"⏳ Pendente — vencida","⏳ Pendente"),IF(INDEX(Atalhos!$C:$C,$H15)="Receita","✔ Recebido","✔ Pago")))) | H15: =Calc!AR7 | I15: =IF(B15="",0,COUNTIFS(tbLancamentos[Descrição],B15,tbLancamentos[Mês],MesNum,tbLancamentos[Ano],AnoSelecionado)) | J15: =IF(B15="",0,COUNTIFS(tbLancamentos[Descrição],B15,tbLancamentos[Mês],MesNum,tbLancamentos[Ano],AnoSelecionado,tbLancamentos[Situação],"Pendente")) | K15: =IF(LEFT(G15,1)="✖",SUMPRODUCT(--(LEFT($G$10:G15,1)="✖")),0) | M15: =IFERROR(DATE(AnoSelecionado,MesNum,MIN(IF(INDEX($D$10:$D$34,MATCH(6,$K$10:$K$34,0))="",1,INDEX($D$10:$D$34,MATCH(6,$K$10:$K$34,0))),DAY(EOMONTH(DATE(AnoSelecionado,MesNum,1),0)))),"") | N15: =IFERROR(INDEX($B$10:$B$34,MATCH(6,$K$10:$K$34,0)),"") | O15: =IFERROR(IF(N(INDEX($E$10:$E$34,MATCH(6,$K$10:$K$34,0)))>0,INDEX($E$10:$E$34,MATCH(6,$K$10:$K$34,0)),""),"") | P15: =IFERROR(INDEX(Atalhos!$C:$C,INDEX($H$10:$H$34,MATCH(6,$K$10:$K$34,0)))&"","") | Q15: =IFERROR(INDEX(Atalhos!$D:$D,INDEX($H$10:$H$34,MATCH(6,$K$10:$K$34,0)))&"","") | R15: =IFERROR(IF(MATCH(6,$K$10:$K$34,0)>0,"Pendente",""),"") | S15: =IFERROR(INDEX(Atalhos!$E:$E,INDEX($H$10:$H$34,MATCH(6,$K$10:$K$34,0)))&"","") | T15: =IFERROR(INDEX(Atalhos!$F:$F,INDEX($H$10:$H$34,MATCH(6,$K$10:$K$34,0)))&"","") | U15: =IFERROR(INDEX(Atalhos!$G:$G,INDEX($H$10:$H$34,MATCH(6,$K$10:$K$34,0)))&"","") | V15: =IFERROR(INDEX(Atalhos!$H:$H,INDEX($H$10:$H$34,MATCH(6,$K$10:$K$34,0)))&"","") | W15: =""
